<?xml version="1.0" encoding="UTF-8"?>
<testng-results skipped="0" failed="1" ignored="0" total="1" passed="0">
  <reporter-output>
  </reporter-output>
  <suite name="Default suite" duration-ms="3737" started-at="2019-12-25T13:32:59Z" finished-at="2019-12-25T13:33:03Z">
    <groups>
    </groups>
    <test name="Default test" duration-ms="3737" started-at="2019-12-25T13:32:59Z" finished-at="2019-12-25T13:33:03Z">
      <class name="com.restassured.testcases.DeleteCustomerTest">
        <test-method status="PASS" signature="setUp()[pri:0, instance:com.restassured.testcases.DeleteCustomerTest@63355449]" name="setUp" is-config="true" duration-ms="450" started-at="2019-12-25T13:32:59Z" finished-at="2019-12-25T13:32:59Z">
          <reporter-output>
          </reporter-output>
        </test-method> <!-- setUp -->
        <test-method status="FAIL" signature="deleteCustomer(java.util.Hashtable)[pri:0, instance:com.restassured.testcases.DeleteCustomerTest@63355449]" name="deleteCustomer" duration-ms="3683" started-at="2019-12-25T13:32:59Z" data-provider="data" finished-at="2019-12-25T13:33:03Z">
          <params>
            <param index="0">
              <value>
                <![CDATA[{id=cus_GQMHWZZe2d27F3}]]>
              </value>
            </param>
          </params>
          <exception class="java.lang.AssertionError">
            <message>
              <![CDATA[ID is not present expected [true] but found [false]]]>
            </message>
            <full-stacktrace>
              <![CDATA[java.lang.AssertionError: ID is not present expected [true] but found [false]
at org.testng.Assert.fail(Assert.java:96)
at org.testng.Assert.failNotEquals(Assert.java:776)
at org.testng.Assert.assertTrue(Assert.java:44)
at com.restassured.testcases.DeleteCustomerTest.deleteCustomer(DeleteCustomerTest.java:35)
at sun.reflect.NativeMethodAccessorImpl.invoke0(Native Method)
at sun.reflect.NativeMethodAccessorImpl.invoke(Unknown Source)
at sun.reflect.DelegatingMethodAccessorImpl.invoke(Unknown Source)
at java.lang.reflect.Method.invoke(Unknown Source)
at org.testng.internal.MethodInvocationHelper.invokeMethod(MethodInvocationHelper.java:124)
at org.testng.internal.Invoker.invokeMethod(Invoker.java:583)
at org.testng.internal.Invoker.invokeTestMethod(Invoker.java:719)
at org.testng.internal.TestMethodWithDataProviderMethodWorker.call(TestMethodWithDataProviderMethodWorker.java:71)
at org.testng.internal.TestMethodWithDataProviderMethodWorker.call(TestMethodWithDataProviderMethodWorker.java:14)
at java.util.concurrent.FutureTask.run(Unknown Source)
at java.util.concurrent.Executors$RunnableAdapter.call(Unknown Source)
at java.util.concurrent.FutureTask.run(Unknown Source)
at java.util.concurrent.ThreadPoolExecutor.runWorker(Unknown Source)
at java.util.concurrent.ThreadPoolExecutor$Worker.run(Unknown Source)
at java.lang.Thread.run(Unknown Source)
]]>
            </full-stacktrace>
          </exception> <!-- java.lang.AssertionError -->
          <reporter-output>
          </reporter-output>
        </test-method> <!-- deleteCustomer -->
        <test-method status="PASS" signature="tearDown()[pri:0, instance:com.restassured.testcases.DeleteCustomerTest@63355449]" name="tearDown" is-config="true" duration-ms="3" started-at="2019-12-25T13:33:03Z" finished-at="2019-12-25T13:33:03Z">
          <reporter-output>
          </reporter-output>
        </test-method> <!-- tearDown -->
      </class> <!-- com.restassured.testcases.DeleteCustomerTest -->
    </test> <!-- Default test -->
  </suite> <!-- Default suite -->
</testng-results>
